{
 "metadata": {
  "name": ""
 },
 "nbformat": 3,
 "nbformat_minor": 0,
 "worksheets": [
  {
   "cells": [
    {
     "cell_type": "heading",
     "level": 1,
     "metadata": {},
     "source": [
      "14.9. Raising an Exception in Response to Another\n",
      "Exception"
     ]
    },
    {
     "cell_type": "markdown",
     "metadata": {},
     "source": [
      "# Problem\n",
      "You want to raise an exception in response to catching a different exception, but want\n",
      "to include information about both exceptions in the traceback.\n",
      "\n",
      "# Solution\n",
      "To chain exceptions, use the `raise from` statement instead of a simple `raise` statement.\n",
      "This will give you information about both errors. For example:"
     ]
    },
    {
     "cell_type": "code",
     "collapsed": false,
     "input": [
      "def example():\n",
      "    try:\n",
      "        int('N/A')\n",
      "    except ValueError as e:\n",
      "        raise RuntimeError('A parsing error occurred') from e"
     ],
     "language": "python",
     "metadata": {},
     "outputs": [],
     "prompt_number": 1
    },
    {
     "cell_type": "code",
     "collapsed": false,
     "input": [
      "example()"
     ],
     "language": "python",
     "metadata": {},
     "outputs": [
      {
       "ename": "RuntimeError",
       "evalue": "A parsing error occurred",
       "output_type": "pyerr",
       "traceback": [
        "\u001b[0;31m---------------------------------------------------------------------------\u001b[0m\n\u001b[0;31mRuntimeError\u001b[0m                              Traceback (most recent call last)",
        "\u001b[0;32m<ipython-input-2-2ec4691f1811>\u001b[0m in \u001b[0;36m<module>\u001b[0;34m()\u001b[0m\n\u001b[0;32m----> 1\u001b[0;31m \u001b[0mexample\u001b[0m\u001b[0;34m(\u001b[0m\u001b[0;34m)\u001b[0m\u001b[0;34m\u001b[0m\u001b[0m\n\u001b[0m",
        "\u001b[0;32m<ipython-input-1-24c2214d0e61>\u001b[0m in \u001b[0;36mexample\u001b[0;34m()\u001b[0m\n\u001b[1;32m      3\u001b[0m         \u001b[0mint\u001b[0m\u001b[0;34m(\u001b[0m\u001b[0;34m'N/A'\u001b[0m\u001b[0;34m)\u001b[0m\u001b[0;34m\u001b[0m\u001b[0m\n\u001b[1;32m      4\u001b[0m     \u001b[0;32mexcept\u001b[0m \u001b[0mValueError\u001b[0m \u001b[0;32mas\u001b[0m \u001b[0me\u001b[0m\u001b[0;34m:\u001b[0m\u001b[0;34m\u001b[0m\u001b[0m\n\u001b[0;32m----> 5\u001b[0;31m         \u001b[0;32mraise\u001b[0m \u001b[0mRuntimeError\u001b[0m\u001b[0;34m(\u001b[0m\u001b[0;34m'A parsing error occurred'\u001b[0m\u001b[0;34m)\u001b[0m \u001b[0;32mfrom\u001b[0m \u001b[0me\u001b[0m\u001b[0;34m\u001b[0m\u001b[0m\n\u001b[0m",
        "\u001b[0;31mRuntimeError\u001b[0m: A parsing error occurred"
       ]
      }
     ],
     "prompt_number": 2
    },
    {
     "cell_type": "markdown",
     "metadata": {},
     "source": [
      "As you can see in the traceback, both exceptions are captured. To catch such an exception, \n",
      "you would use a normal `except` statement. However, you can look at the `__cause__`\n",
      "attribute of the exception object to follow the exception chain should you wish. For\n",
      "example:"
     ]
    },
    {
     "cell_type": "code",
     "collapsed": false,
     "input": [
      "try:\n",
      "    example()\n",
      "except RuntimeError as e:\n",
      "    print(\"It didn't work:\", e)\n",
      "    if e.__cause__:\n",
      "        print('Cause:', e.__cause__)"
     ],
     "language": "python",
     "metadata": {},
     "outputs": [
      {
       "output_type": "stream",
       "stream": "stdout",
       "text": [
        "It didn't work: A parsing error occurred\n",
        "Cause: invalid literal for int() with base 10: 'N/A'\n"
       ]
      }
     ],
     "prompt_number": 3
    },
    {
     "cell_type": "markdown",
     "metadata": {},
     "source": [
      "An implicit form of chained exceptions occurs when another exception gets raised \n",
      "inside an `except` block. For example:"
     ]
    },
    {
     "cell_type": "code",
     "collapsed": false,
     "input": [
      "def example2():\n",
      "    try:\n",
      "        int('N/A')\n",
      "    except ValueError as e:\n",
      "        print(\"Couldn't parse:\", err)"
     ],
     "language": "python",
     "metadata": {},
     "outputs": [],
     "prompt_number": 4
    },
    {
     "cell_type": "code",
     "collapsed": false,
     "input": [
      "example2()"
     ],
     "language": "python",
     "metadata": {},
     "outputs": [
      {
       "ename": "NameError",
       "evalue": "name 'err' is not defined",
       "output_type": "pyerr",
       "traceback": [
        "\u001b[0;31m---------------------------------------------------------------------------\u001b[0m\n\u001b[0;31mNameError\u001b[0m                                 Traceback (most recent call last)",
        "\u001b[0;32m<ipython-input-5-948b38befdd2>\u001b[0m in \u001b[0;36m<module>\u001b[0;34m()\u001b[0m\n\u001b[0;32m----> 1\u001b[0;31m \u001b[0mexample2\u001b[0m\u001b[0;34m(\u001b[0m\u001b[0;34m)\u001b[0m\u001b[0;34m\u001b[0m\u001b[0m\n\u001b[0m",
        "\u001b[0;32m<ipython-input-4-931cd63286e7>\u001b[0m in \u001b[0;36mexample2\u001b[0;34m()\u001b[0m\n\u001b[1;32m      3\u001b[0m         \u001b[0mint\u001b[0m\u001b[0;34m(\u001b[0m\u001b[0;34m'N/A'\u001b[0m\u001b[0;34m)\u001b[0m\u001b[0;34m\u001b[0m\u001b[0m\n\u001b[1;32m      4\u001b[0m     \u001b[0;32mexcept\u001b[0m \u001b[0mValueError\u001b[0m \u001b[0;32mas\u001b[0m \u001b[0me\u001b[0m\u001b[0;34m:\u001b[0m\u001b[0;34m\u001b[0m\u001b[0m\n\u001b[0;32m----> 5\u001b[0;31m         \u001b[0mprint\u001b[0m\u001b[0;34m(\u001b[0m\u001b[0;34m\"Couldn't parse:\"\u001b[0m\u001b[0;34m,\u001b[0m \u001b[0merr\u001b[0m\u001b[0;34m)\u001b[0m\u001b[0;34m\u001b[0m\u001b[0m\n\u001b[0m",
        "\u001b[0;31mNameError\u001b[0m: name 'err' is not defined"
       ]
      }
     ],
     "prompt_number": 5
    },
    {
     "cell_type": "markdown",
     "metadata": {},
     "source": [
      "In this example, you get information about both exceptions, but the interpretation is a\n",
      "bit different. In this case, the `NameError` exception is raised as the result of a \n",
      "programming error, not in direct response to the parsing error. For this case, the `__cause__`\n",
      "attribute of an exception is not set. Instead, a `__context__` attribute is set to the prior\n",
      "exception.\n",
      "\n",
      "If, for some reason, you want to suppress chaining, use `raise from None`:"
     ]
    },
    {
     "cell_type": "code",
     "collapsed": false,
     "input": [
      "def example3():\n",
      "    try:\n",
      "        int('N/A')\n",
      "    except ValueError:\n",
      "        raise RuntimeError('A parsing error occurred') from None"
     ],
     "language": "python",
     "metadata": {},
     "outputs": [],
     "prompt_number": 6
    },
    {
     "cell_type": "code",
     "collapsed": false,
     "input": [
      "example3()"
     ],
     "language": "python",
     "metadata": {},
     "outputs": [
      {
       "ename": "RuntimeError",
       "evalue": "A parsing error occurred",
       "output_type": "pyerr",
       "traceback": [
        "\u001b[0;31m---------------------------------------------------------------------------\u001b[0m\n\u001b[0;31mRuntimeError\u001b[0m                              Traceback (most recent call last)",
        "\u001b[0;32m<ipython-input-7-2b8f3cab1522>\u001b[0m in \u001b[0;36m<module>\u001b[0;34m()\u001b[0m\n\u001b[0;32m----> 1\u001b[0;31m \u001b[0mexample3\u001b[0m\u001b[0;34m(\u001b[0m\u001b[0;34m)\u001b[0m\u001b[0;34m\u001b[0m\u001b[0m\n\u001b[0m",
        "\u001b[0;32m<ipython-input-6-b3c447a3bf54>\u001b[0m in \u001b[0;36mexample3\u001b[0;34m()\u001b[0m\n\u001b[1;32m      3\u001b[0m         \u001b[0mint\u001b[0m\u001b[0;34m(\u001b[0m\u001b[0;34m'N/A'\u001b[0m\u001b[0;34m)\u001b[0m\u001b[0;34m\u001b[0m\u001b[0m\n\u001b[1;32m      4\u001b[0m     \u001b[0;32mexcept\u001b[0m \u001b[0mValueError\u001b[0m\u001b[0;34m:\u001b[0m\u001b[0;34m\u001b[0m\u001b[0m\n\u001b[0;32m----> 5\u001b[0;31m         \u001b[0;32mraise\u001b[0m \u001b[0mRuntimeError\u001b[0m\u001b[0;34m(\u001b[0m\u001b[0;34m'A parsing error occurred'\u001b[0m\u001b[0;34m)\u001b[0m \u001b[0;32mfrom\u001b[0m \u001b[0;32mNone\u001b[0m\u001b[0;34m\u001b[0m\u001b[0m\n\u001b[0m",
        "\u001b[0;31mRuntimeError\u001b[0m: A parsing error occurred"
       ]
      }
     ],
     "prompt_number": 7
    },
    {
     "cell_type": "markdown",
     "metadata": {},
     "source": [
      "# Discussion\n",
      "In designing code, you should give careful attention to use of the `raise` statement inside\n",
      "of other `except` blocks. In most cases, such `raise` statements should probably be\n",
      "changed to `raise` from statements. That is, you should prefer this style:\n",
      "```python\n",
      "try:\n",
      "    \u2026\n",
      "except SomeException as e:\n",
      "    raise DifferentException() from e\n",
      "```\n",
      "The reason for doing this is that you are explicitly chaining the causes together. That is,\n",
      "the `DifferentException` is being raised in direct response to getting a `SomeException`. \n",
      "This relationship will be explicitly stated in the resulting traceback.\n",
      "\n",
      "If you write your code in the following style, you still get a chained exception, but it\u2019s\n",
      "often not clear if the exception chain was intentional or the result of an unforeseen\n",
      "programming error:\n",
      "```python\n",
      "try:\n",
      "    \u2026\n",
      "except SomeException:\n",
      "    raise DifferentException()\n",
      "```\n",
      "When you use `raise from`, you\u2019re making it clear that you meant to raise the second\n",
      "exception.\n",
      "\n",
      "Resist the urge to suppress exception information, as shown in the last example. Although \n",
      "suppressing exception information can lead to smaller tracebacks, it also discards \n",
      "information that might be useful for debugging. All things being equal, it\u2019s often\n",
      "best to keep as much information as possible."
     ]
    }
   ],
   "metadata": {}
  }
 ]
}